<?xml version='1.0'?>
<sdf version='1.6'>
  <model name='mouse'>
    <link name='base'>
      <pose>0 -0 0.005 0 -0 0</pose>
      <inertial>
        <pose frame=''>0 0.01 0 0 -0 0</pose>
        <mass>0.5</mass>
        <inertia>
          <ixx>0.00022083</ixx>
          <ixy>0</ixy>
          <ixz>0</ixz>
          <iyy>0.00022083</iyy>
          <iyz>0</iyz>
          <izz>0.00040833</izz>
        </inertia>
      </inertial>
      <visual name='castor_visual'>
        <pose frame=''>0 0.03 -0.02 0 -0 0</pose>
        <geometry>
          <sphere>
            <radius>0.005</radius>
          </sphere>
        </geometry>
      </visual>
      <visual name='visual'>
        <pose frame=''>0 0 -0.01 0 -0 0</pose>
        <geometry>
          <box>
            <size>0.07 0.07 0.02</size>
          </box>
        </geometry>
        <material>
          <script>
            <uri>file://media/materials/scripts/gazebo.material</uri>
            <name>Gazebo/Blue</name>
          </script>
        </material>
      </visual>
      <collision name='castor_collision'>
        <pose frame=''>0 0.03 -0.02 0 -0 0</pose>
        <geometry>
          <sphere>
            <radius>0.005</radius>
          </sphere>
        </geometry>
        <surface>
          <friction>
            <ode>
              <mu>0</mu>
              <mu2>0</mu2>
              <fdir1>0 0 0</fdir1>
              <slip1>1</slip1>
              <slip2>1</slip2>
            </ode>
            <torsional>
              <ode>
                <slip>1</slip>
              </ode>
            </torsional>
          </friction>
          <contact>
            <ode>
              <soft_cfm>0</soft_cfm>
              <soft_erp>0.2</soft_erp>
              <kp>1000000.0</kp>
              <kd>100.0</kd>
              <max_vel>0.01</max_vel>
              <min_depth>0</min_depth>
            </ode>
          </contact>
        </surface>
      </collision>
      <collision name='collision'>
        <pose frame=''>0 0 -0.01 0 0 0</pose>
        <geometry>
          <box>
            <size>0.07 0.07 0.02</size>
          </box>
        </geometry>
        <surface>
          <friction>
            <ode>
              <mu>1</mu>
              <mu2>1</mu2>
              <fdir1>0 0 0</fdir1>
              <slip1>0</slip1>
              <slip2>0</slip2>
            </ode>
          </friction>
          <contact>
            <ode>
              <soft_cfm>0</soft_cfm>
              <soft_erp>0.2</soft_erp>
              <kp>1e13</kp>
              <kd>1.0</kd>
              <max_vel>0.01</max_vel>
              <min_depth>0</min_depth>
            </ode>
          </contact>
        </surface>
      </collision>
      <sensor name="laser" type="ray">
        <pose>0 0.02 0.004 0 0 0</pose>
        <ray>
          <scan>
            <horizontal>
              <samples>3</samples>
              <resolution>1</resolution>
              <min_angle>0.52359877</min_angle>
              <max_angle>2.61799387</max_angle>
            </horizontal>
          </scan>
          <range>
            <min>0.01</min>
            <max>0.2</max>
            <resolution>0.005</resolution>
          </range>
        </ray>
        <plugin name="laser" filename="libRayPlugin.so" />
        <always_on>1</always_on>
        <update_rate>10</update_rate>
        <visualize>true</visualize>
      </sensor>
    </link>
    <link name='right_wheel'>
      <pose frame=''>0.04 0.0 0 0 1.57079 0</pose>
      <inertial>
        <mass>0.01</mass>
        <inertia>
          <ixx>2.3e-06</ixx>
          <ixy>0</ixy>
          <ixz>0</ixz>
          <iyy>2.3e-06</iyy>
          <iyz>0</iyz>
          <izz>4.5e-06</izz>
        </inertia>
        <pose frame=''>0 0 0 0 -0 0</pose>
      </inertial>
      <self_collide>0</self_collide>
      <kinematic>0</kinematic>
      <gravity>1</gravity>
      <visual name='visual'>
        <pose frame=''>0 0 0 0 -0 0</pose>
        <geometry>
          <cylinder>
            <radius>0.02</radius>
            <length>0.01</length>
          </cylinder>
        </geometry>
        <material>
          <lighting>1</lighting>
          <script>
            <uri>file://media/materials/scripts/gazebo.material</uri>
            <name>Gazebo/Grey</name>
          </script>
          <ambient>0.3 0.3 0.3 1</ambient>
          <diffuse>0.7 0.7 0.7 1</diffuse>
          <specular>0.01 0.01 0.01 1</specular>
          <emissive>0 0 0 1</emissive>
          <shader type='vertex'>
            <normal_map>__default__</normal_map>
          </shader>
        </material>
        <cast_shadows>1</cast_shadows>
        <transparency>0</transparency>
      </visual>
      <collision name='collision'>
        <laser_retro>0</laser_retro>
        <max_contacts>10</max_contacts>
        <pose frame=''>0 0 0 0 -0 0</pose>
        <geometry>
          <cylinder>
            <radius>0.02</radius>
            <length>0.01</length>
          </cylinder>
        </geometry>
        <surface>
          <friction>
            <ode>
              <mu>10</mu>
              <mu2>10</mu2>
            </ode>
            <torsional>
              <coefficient>1</coefficient>
              <patch_radius>0</patch_radius>
              <surface_radius>0</surface_radius>
              <use_patch_radius>1</use_patch_radius>
              <ode>
                <slip>0</slip>
              </ode>
            </torsional>
          </friction>
          <bounce>
            <restitution_coefficient>0</restitution_coefficient>
            <threshold>1e+06</threshold>
          </bounce>
          <contact>
            <collide_without_contact>0</collide_without_contact>
            <collide_without_contact_bitmask>1</collide_without_contact_bitmask>
            <collide_bitmask>1</collide_bitmask>
            <ode>
              <soft_cfm>0</soft_cfm>
              <soft_erp>0.2</soft_erp>
              <kp>1000000.0</kp>
              <kd>100.0</kd>
              <max_vel>0.01</max_vel>
              <min_depth>0</min_depth>
            </ode>
          </contact>
        </surface>
      </collision>
    </link>
    <link name='left_wheel'>
      <pose frame=''>-0.04 0.0 0 0 1.57079 0</pose>
      <inertial>
        <mass>0.01</mass>
        <inertia>
          <ixx>2.3e-06</ixx>
          <ixy>0</ixy>
          <ixz>0</ixz>
          <iyy>2.3e-06</iyy>
          <iyz>0</iyz>
          <izz>4.5e-06</izz>
        </inertia>
      </inertial>
      <self_collide>0</self_collide>
      <kinematic>0</kinematic>
      <visual name='visual'>
        <pose frame=''>0 0 0 0 -0 0</pose>
        <geometry>
          <cylinder>
            <radius>0.02</radius>
            <length>0.01</length>
          </cylinder>
        </geometry>
        <material>
          <lighting>1</lighting>
          <script>
            <uri>file://media/materials/scripts/gazebo.material</uri>
            <name>Gazebo/Grey</name>
          </script>
          <ambient>0.3 0.3 0.3 1</ambient>
          <diffuse>0.7 0.7 0.7 1</diffuse>
          <specular>0.01 0.01 0.01 1</specular>
          <emissive>0 0 0 1</emissive>
          <shader type='vertex'>
            <normal_map>__default__</normal_map>
          </shader>
        </material>
        <cast_shadows>1</cast_shadows>
        <transparency>0</transparency>
      </visual>
      <collision name='collision'>
        <laser_retro>0</laser_retro>
        <max_contacts>10</max_contacts>
        <pose frame=''>0 0 0 0 -0 0</pose>
        <geometry>
          <cylinder>
            <radius>0.02</radius>
            <length>0.01</length>
          </cylinder>
        </geometry>
        <surface>
          <friction>
            <ode>
              <mu>10</mu>
              <mu2>10</mu2>
            </ode>
            <torsional>
              <coefficient>1</coefficient>
              <patch_radius>0</patch_radius>
              <surface_radius>0</surface_radius>
              <use_patch_radius>1</use_patch_radius>
              <ode>
                <slip>0</slip>
              </ode>
            </torsional>
          </friction>
          <bounce>
            <restitution_coefficient>0</restitution_coefficient>
            <threshold>1e+06</threshold>
          </bounce>
          <contact>
            <collide_without_contact>0</collide_without_contact>
            <collide_without_contact_bitmask>1</collide_without_contact_bitmask>
            <collide_bitmask>1</collide_bitmask>
            <ode>
              <soft_cfm>0</soft_cfm>
              <soft_erp>0.2</soft_erp>
              <kp>1000000.0</kp>
              <kd>100.0</kd>
              <max_vel>0.01</max_vel>
              <min_depth>0</min_depth>
            </ode>
          </contact>
        </surface>
      </collision>
    </link>
    <joint name='left_wheel_joint' type='revolute'>
      <parent>base</parent>
      <child>left_wheel</child>
      <pose frame=''>0 0 0 0 -0 0</pose>
      <axis>
        <xyz>0 0 -1</xyz>
        <use_parent_model_frame>0</use_parent_model_frame>
        <limit>
          <lower>-1.79769e+308</lower>
          <upper>1.79769e+308</upper>
          <effort>-1</effort>
          <velocity>100</velocity>
        </limit>
        <dynamics>
          <spring_reference>0</spring_reference>
          <spring_stiffness>0</spring_stiffness>
          <damping>0.01</damping>
          <friction>0</friction>
        </dynamics>
      </axis>
      <physics>
        <ode>
          <implicit_spring_damper>true</implicit_spring_damper>
          <limit>
            <cfm>0</cfm>
            <erp>0.2</erp>
          </limit>
          <suspension>
            <cfm>0</cfm>
            <erp>0.2</erp>
          </suspension>
        </ode>
      </physics>
    </joint>
    <joint name='right_wheel_joint' type='revolute'>
      <parent>base</parent>
      <child>right_wheel</child>
      <pose frame=''>0 0 0 0 -0 0</pose>
      <axis>
        <xyz>0 0 -1</xyz>
        <use_parent_model_frame>0</use_parent_model_frame>
        <limit>
          <lower>-1.79769e+308</lower>
          <upper>1.79769e+308</upper>
          <effort>-1</effort>
          <velocity>100</velocity>
        </limit>
        <dynamics>
          <spring_reference>0</spring_reference>
          <spring_stiffness>0</spring_stiffness>
          <damping>0.01</damping>
          <friction>0</friction>
        </dynamics>
      </axis>
      <physics>
        <ode>
          <implicit_spring_damper>true</implicit_spring_damper>
          <limit>
            <cfm>0</cfm>
            <erp>0.2</erp>
          </limit>
          <suspension>
            <cfm>0</cfm>
            <erp>0.2</erp>
          </suspension>
        </ode>
      </physics>
    </joint>
    <static>0</static>
    <allow_auto_disable>1</allow_auto_disable>
		<plugin name="mouse_plugin" filename="libMousePlugin.so">
      <left_wheel_joint>left_wheel_joint</left_wheel_joint>
      <right_wheel_joint>right_wheel_joint</right_wheel_joint>
      <body>base</body>
		</plugin>
  </model>
</sdf>
